<!--
  Copyright 2018 The Dalu Robotech Authors

  Licensed under the Apache License, Version 2.0 (the "License");
  you may not use this file except in compliance with the License.
  You may obtain a copy of the License at

       http://www.apache.org/licenses/LICENSE-2.0

  Unless required by applicable law or agreed to in writing, software
  distributed under the License is distributed on an "AS IS" BASIS,
  WITHOUT WARRANTIES OR CONDITIONS OF ANY KIND, either express or implied.
  See the License for the specific language governing permissions and
  limitations under the License.
-->

<robot name="andi">
  <material name="orange">
    <color rgba="1.0 0.5 0.2 1" />
  </material>
  <material name="gray">
    <color rgba="0.2 0.2 0.2 1" />
  </material>
  
  <link name="base_link" >
      <visual>
      <geometry>
        <box size="0.81 0.635 0.20"/>
      </geometry>
      <origin rpy="0 0 0" xyz="0 0 0.1"/>
      <material name="orange" />
    </visual>
  </link> 
  
  <link name="base_imu_link">
    <visual>
      <origin xyz="0 0 0" />
      <geometry>
        <box size="0.06 0.04 0.02" />
      </geometry>
      <material name="orange" />
    </visual>
  </link>
  
  <link name="gps">
    <visual>
      <origin xyz="0 0 0" />
      <geometry>
        <box size="0.06 0.04 0.02" />
      </geometry>
      <material name="orange" />
    </visual>
  </link>
  
  <link name="base_tfmini0">
    <visual>
      <origin xyz="0 0 0" />
      <geometry>
        <box size="0.06 0.04 0.02" />
      </geometry>
      <material name="orange" />
    </visual>
  </link>
  
  <link name="base_tfmini1">
    <visual>
      <origin xyz="0 0 0" />
      <geometry>
        <box size="0.06 0.04 0.02" />
      </geometry>
      <material name="orange" />
    </visual>
  </link>

  <link name="base_laser">
    <visual>
      <origin xyz="0 0 0" />
      <geometry>
        <cylinder length="0.05" radius="0.03" />
      </geometry>
      <material name="gray" />
    </visual>
  </link>

  <link name="zed_camera_center">
    <visual>
      <origin xyz="0 -0.03 0" />
      <geometry>
        <box size="0.033 0.175 0.03" />
      </geometry>
      <material name="gray" />
    </visual>
  </link>
  
  <link name="base_ultrasound0">
    <visual>
      <origin xyz="0 0 0" />
      <geometry>
        <cylinder length="0.05" radius="0.03" />
      </geometry>
      <material name="gray" />
    </visual>
  </link>
  
  <link name="base_ultrasound1">
    <visual>
      <origin xyz="0 0 0" />
      <geometry>
        <cylinder length="0.05" radius="0.03" />
      </geometry>
      <material name="gray" />
    </visual>
  </link>

  <link name="base_ultrasound2">
    <visual>
      <origin xyz="0 0 0" />
      <geometry>
        <cylinder length="0.05" radius="0.03" />
      </geometry>
      <material name="gray" />
    </visual>
  </link>
  
  <link name="base_ultrasound3">
    <visual>
      <origin xyz="0 0 0" />
      <geometry>
        <cylinder length="0.05" radius="0.03" />
      </geometry>
      <material name="gray" />
    </visual>
  </link>
  
  <link name="base_ultrasound4">
    <visual>
      <origin xyz="0 0 0" />
      <geometry>
        <cylinder length="0.05" radius="0.03" />
      </geometry>
      <material name="gray" />
    </visual>
  </link>
  
  <link name="base_ultrasound5">
    <visual>
      <origin xyz="0 0 0" />
      <geometry>
        <cylinder length="0.05" radius="0.03" />
      </geometry>
      <material name="gray" />
    </visual>
  </link>
  
  <link name="base_ultrasound6">
    <visual>
      <origin xyz="0 0 0" />
      <geometry>
        <cylinder length="0.05" radius="0.03" />
      </geometry>
      <material name="gray" />
    </visual>
  </link>
  
  <link name="base_ultrasound7">
    <visual>
      <origin xyz="0 0 0" />
      <geometry>
        <cylinder length="0.05" radius="0.03" />
      </geometry>
      <material name="gray" />
    </visual>
  </link>
  
  <link name="base_ultrasound8">
    <visual>
      <origin xyz="0 0 0" />
      <geometry>
        <cylinder length="0.05" radius="0.03" />
      </geometry>
      <material name="gray" />
    </visual>
  </link>
  
  <link name="base_ultrasound9">
    <visual>
      <origin xyz="0 0 0" />
      <geometry>
        <cylinder length="0.05" radius="0.03" />
      </geometry>
      <material name="gray" />
    </visual>
  </link>
  
  <link name="base_ultrasound10">
    <visual>
      <origin xyz="0 0 0" />
      <geometry>
        <cylinder length="0.05" radius="0.03" />
      </geometry>
      <material name="gray" />
    </visual>
  </link>
  
  <link name="base_ultrasound11">
    <visual>
      <origin xyz="0 0 0" />
      <geometry>
        <cylinder length="0.05" radius="0.03" />
      </geometry>
      <material name="gray" />
    </visual>
  </link>

  <joint name="imu_link_joint" type="fixed">
    <parent link="base_link" />
    <child link="base_imu_link" />
    <origin xyz="0.3 0 0.27" />
  </joint>
  
  <joint name="gps_joint" type="fixed">
    <parent link="base_link" />
    <child link="gps" />
    <origin xyz="0.0 0 1.2" />
  </joint>
  
  <joint name="tfmini0_joint" type="fixed">
    <parent link="base_link" />
    <child link="base_tfmini0" />
    <origin rpy="0 0.2774 0" xyz="0.3 0.1 0.27" />
  </joint>
  
  <joint name="tfmini1_joint" type="fixed">
    <parent link="base_link" />
    <child link="base_tfmini1" />
    <origin rpy="0 0.2774 0" xyz="0.3 -0.1 0.27" />
  </joint>

  <joint name="laser_link_joint" type="fixed">
    <parent link="base_link" />
    <child link="base_laser" />
    <origin rpy="0 0 3.141593" xyz="0.31 0 0.34" />
  </joint>

  <joint name="zed_link_joint" type="fixed">
    <parent link="base_link" />
    <child link="zed_camera_center" />
    <origin xyz="0.27 0 0.60" />
  </joint>
  
  <joint name="ultrasound0_link_joint" type="fixed">
    <parent link="base_link" />
    <child link="base_ultrasound0" />
    <origin rpy="0 0 0.785" xyz="0.27 0.1834 0.34" />
  </joint>
  
  <joint name="ultrasound1_link_joint" type="fixed">
    <parent link="base_link" />
    <child link="base_ultrasound1" />
    <origin rpy="0 0 0.174" xyz="0.3066 0.083 0.34" />
  </joint>
  
  <joint name="ultrasound2_link_joint" type="fixed">
    <parent link="base_link" />
    <child link="base_ultrasound2" />
    <origin rpy="0 0 -0.174" xyz="0.3066 -0.083 0.34" />
  </joint>
  
  <joint name="ultrasound3_link_joint" type="fixed">
    <parent link="base_link" />
    <child link="base_ultrasound3" />
    <origin rpy="0 0 -0.785" xyz="0.27 -0.1834 0.34" />
  </joint>
  
  <joint name="ultrasound4_link_joint" type="fixed">
    <parent link="base_link" />
    <child link="base_ultrasound4" />
    <origin rpy="0 0 -1.57" xyz="0.109 -0.2275 0.34" />
  </joint>
  
  <joint name="ultrasound5_link_joint" type="fixed">
    <parent link="base_link" />
    <child link="base_ultrasound5" />
    <origin rpy="0 0 -1.57" xyz="-0.151 -0.2494 0.34" />
  </joint>
  
  
  <joint name="ultrasound6_link_joint" type="fixed">
    <parent link="base_link" />
    <child link="base_ultrasound6" />
    <origin rpy="0 0 -2.355" xyz="-0.27 -0.1834 0.34" />
  </joint>
  
  <joint name="ultrasound7_link_joint" type="fixed">
    <parent link="base_link" />
    <child link="base_ultrasound7" />
    <origin rpy="0 0 3.14" xyz="-0.2951 -0.1185 0.34" />
  </joint>
  
  <joint name="ultrasound8_link_joint" type="fixed">
    <parent link="base_link" />
    <child link="base_ultrasound8" />
    <origin rpy="0 0 3.14" xyz="-0.2951 0.1185 0.34" />
  </joint>
  
  <joint name="ultrasound9_link_joint" type="fixed">
    <parent link="base_link" />
    <child link="base_ultrasound9" />
    <origin rpy="0 0 2.355" xyz="-0.27 0.1834 0.34" />
  </joint>
  
  <joint name="ultrasound10_link_joint" type="fixed">
    <parent link="base_link" />
    <child link="base_ultrasound10" />
    <origin rpy="0 0 1.57" xyz="-0.151 0.2494 0.34" />
  </joint>
  
  <joint name="ultrasound11_link_joint" type="fixed">
    <parent link="base_link" />
    <child link="base_ultrasound11" />
    <origin rpy="0 0 1.57" xyz="0.109 0.2275 0.34" />
  </joint>

<!-- Left Camera -->

    <joint name="zed_left_camera_joint" type="fixed">
        <parent link="zed_camera_center"/>
        <child link="zed_left_camera_frame"/>
        <origin xyz="0 0.03 0" rpy="0 0 0" />
    </joint>

    <link name="zed_left_camera_frame" />

    <joint name="zed_left_camera_optical_joint" type="fixed">
        <origin xyz="0 0 0" rpy="-1.57079632679 0.0 -1.57079632679"/>
        <parent link="zed_left_camera_frame"/>
        <child link="zed_left_camera_optical_frame"/>
    </joint>

    <link name="zed_left_camera_optical_frame"/>

<!-- Right Camera -->

    <joint name="zed_right_camera_joint" type="fixed">
        <parent link="zed_camera_center"/>
        <child link="zed_right_camera_frame"/>
        <origin xyz="0 -0.03 0" rpy="0 0 0" />
    </joint>

    <link name="zed_right_camera_frame" />

    <joint name="zed_right_camera_optical_joint" type="fixed">
        <origin xyz="0 0 0" rpy="-1.57079632679 0.0 -1.57079632679"/>
        <parent link="zed_right_camera_frame"/>
        <child link="zed_right_camera_optical_frame"/>
    </joint>

    <link name="zed_right_camera_optical_frame"/>  

<!-- IMU -->    

    <joint name="zed_imu_link_joint" type="floating">
        <parent link="zed_camera_center"/>
        <child link="imu_link"/>
        <origin xyz="0 0 0" rpy="0 0 0" />
    </joint>
    <link name="imu_link" />    
</robot>
